Traceback (most recent call last):
  File "/home/storm/StramKek/Prog/Python/GitPythonTest/Tests/MouseCheck/get_mouse_position.py", line 34, in <module>
    CursorPosition = GetMousePosition()
  File "/home/storm/StramKek/Prog/Python/GitPythonTest/Tests/MouseCheck/get_mouse_position.py", line 10, in GetMousePosition
    previous_position = current_position = position()
  File "/usr/lib/python3.8/site-packages/pyautogui/__init__.py", line 753, in position
    posx, posy = platformModule._position()
  File "/usr/lib/python3.8/site-packages/pyautogui/_pyautogui_x11.py", line 32, in _position
    coord = _display.screen().root.query_pointer()._data
  File "/usr/lib/python3.8/site-packages/Xlib/xobject/drawable.py", line 561, in query_pointer
    return request.QueryPointer(display = self.display,
  File "/usr/lib/python3.8/site-packages/Xlib/protocol/rq.py", line 1481, in __init__
    self.reply()
  File "/usr/lib/python3.8/site-packages/Xlib/protocol/rq.py", line 1493, in reply
    self._display.send_and_recv(request = self._serial)
  File "/usr/lib/python3.8/site-packages/Xlib/protocol/display.py", line 517, in send_and_recv
    raise err
  File "/usr/lib/python3.8/site-packages/Xlib/protocol/display.py", line 511, in send_and_recv
    rs, ws, es = select.select([self.socket], writeset, [], timeout)
OSError: [Errno 9] Bad file descriptor
